Traceback (most recent call last):
  File "/opt/hostedtoolcache/Python/3.7.13/x64/lib/python3.7/site-packages/jupyter_cache/executors/utils.py", line 56, in single_nb_execution
    record_timing=False,
  File "/opt/hostedtoolcache/Python/3.7.13/x64/lib/python3.7/site-packages/nbclient/client.py", line 1204, in execute
    return NotebookClient(nb=nb, resources=resources, km=km, **kwargs).execute()
  File "/opt/hostedtoolcache/Python/3.7.13/x64/lib/python3.7/site-packages/nbclient/util.py", line 84, in wrapped
    return just_run(coro(*args, **kwargs))
  File "/opt/hostedtoolcache/Python/3.7.13/x64/lib/python3.7/site-packages/nbclient/util.py", line 62, in just_run
    return loop.run_until_complete(coro)
  File "/opt/hostedtoolcache/Python/3.7.13/x64/lib/python3.7/asyncio/base_events.py", line 587, in run_until_complete
    return future.result()
  File "/opt/hostedtoolcache/Python/3.7.13/x64/lib/python3.7/site-packages/nbclient/client.py", line 664, in async_execute
    cell, index, execution_count=self.code_cells_executed + 1
  File "/opt/hostedtoolcache/Python/3.7.13/x64/lib/python3.7/site-packages/nbclient/client.py", line 965, in async_execute_cell
    await self._check_raise_for_error(cell, cell_index, exec_reply)
  File "/opt/hostedtoolcache/Python/3.7.13/x64/lib/python3.7/site-packages/nbclient/client.py", line 862, in _check_raise_for_error
    raise CellExecutionError.from_cell_and_msg(cell, exec_reply_content)
nbclient.exceptions.CellExecutionError: An error occurred while executing the following cell:
------------------
%matplotlib inline

import matplotlib.pyplot as plt
from pennylane import numpy as np
import pennylane as qml
import warnings
warnings.filterwarnings('ignore')

import mitiq as mq
from mitiq.zne.scaling import fold_global
from mitiq.zne.inference import RichardsonFactory
from pennylane.transforms import mitigate_with_zne
from qiskit.providers.aer import AerSimulator
import qiskit.providers.aer.noise as noise
------------------

[0;31m---------------------------------------------------------------------------[0m
[0;31mModuleNotFoundError[0m                       Traceback (most recent call last)
[0;32m/tmp/ipykernel_1832/1348160367.py[0m in [0;36m<module>[0;34m[0m
[1;32m      7[0m [0mwarnings[0m[0;34m.[0m[0mfilterwarnings[0m[0;34m([0m[0;34m'ignore'[0m[0;34m)[0m[0;34m[0m[0;34m[0m[0m
[1;32m      8[0m [0;34m[0m[0m
[0;32m----> 9[0;31m [0;32mimport[0m [0mmitiq[0m [0;32mas[0m [0mmq[0m[0;34m[0m[0;34m[0m[0m
[0m[1;32m     10[0m [0;32mfrom[0m [0mmitiq[0m[0;34m.[0m[0mzne[0m[0;34m.[0m[0mscaling[0m [0;32mimport[0m [0mfold_global[0m[0;34m[0m[0;34m[0m[0m
[1;32m     11[0m [0;32mfrom[0m [0mmitiq[0m[0;34m.[0m[0mzne[0m[0;34m.[0m[0minference[0m [0;32mimport[0m [0mRichardsonFactory[0m[0;34m[0m[0;34m[0m[0m

[0;31mModuleNotFoundError[0m: No module named 'mitiq'
ModuleNotFoundError: No module named 'mitiq'

